# 简介
当程序运行时，外部环境不一定总能满足条件，例如：我们准备向磁盘中写入一些数据，但磁盘的剩余空间可能不足，即使我们在写入前已检查剩余空间，写入过程中磁盘仍然可能被其他程序填满，从而导致写入失败。

阻止程序正确运行的问题被统称为“异常(Exception)”，我们可以在编码阶段对常见的异常进行处理，最大程度上确保程序运行稳定。

Java中的异常继承自Throwable类，随后可以分为两个大类：Error和Exception。Error表示系统级错误，通常由JVM汇报，包括：虚拟机错误、内存溢出、线程死锁等，开发者在编码阶段无需处理此类错误，因为它们出现之后当前程序甚至整个系统可能崩溃，需要重启程序或系统、扩充物理内存或调整代码逻辑才能解决问题。Exception则表示用户态错误，包括：网络不可用、磁盘已满、用户输入参数错误等，此类错误仅影响程序正在执行的语句，开发者可以提醒用户解决问题后重试。

Java中常见的异常如下文表格所示：

<div align="center">

|            异常类名            |       含义       |                           示例                            |
| :----------------------------: | :--------------: | :-------------------------------------------------------: |
|      NullPointerException      |    空指针异常    |           `String text = null; text.length();`            |
|       ClassCastException       |   类型转换异常   |              `Object a = "A"; (Integer) a;`               |
| ArrayIndexOutOfBoundsException | 数组下标越界异常 | `int[] array = new int[]{0, 1, 2}; int item = array[10];` |
|      ArithmeticException       |     算术异常     |            `int a = 10, b = 0; int z = a / b`             |
|          IOException           |     I/O异常      |                  写入数据时目标磁盘已满                   |
|          SQLException          |     SQL异常      |                        SQL语法错误                        |

</div>


# 捕获异常
## 简介
默认情况下，当程序运行中某个语句出现异常时，其所属线程就会立刻终止，相关资源无法得到释放，外部组件也不会感知到该事件。

我们可以使用 `try-catch-finally` 语句捕获可能出现的异常，并释放当前线程所关联的资源或者向用户展示错误提示信息，相关语法如下文代码块所示：

```text
try {
    <可能会发生异常的语句...>
} catch (Exception e) {
    <异常处理语句...>
} finally {
    <公共语句...>
}
```

`try` 块中的语句将会按照顺序执行，一旦某个语句出现异常，程序就会忽略后续语句，并将控制权移交给 `catch` 块，按照顺序执行其中的异常处理语句。 `finally` 块中的语句用于执行善后操作，不管是否发生异常都会在最后被执行，我们可以在此处放置关闭I/O流、删除临时文件等语句，若我们不需要任何善后操作，也可以省略 `finally` 块。

## 基本应用
下文示例展示了异常捕获语句的基本使用方法：

🔴 示例一：异常捕获语句的基本应用。

在本示例中，我们将两个整数相除的语句放置在 `try-catch-finally` 语句中，使用不同的值多次运行程序，对比程序的行为。

第一步，我们使用非零的除数运行程序。

"TestException.java":

```java
try {
    int i = 10 / 5;
    System.out.println("i=" + i);
} catch (Exception e) {
    System.out.println("发生异常！");
} finally {
    System.out.println("善后工作完成！");
}
System.out.println("整个程序已结束！");
```

此时运行示例程序，并查看控制台输出信息：

```text
i=2
善后工作完成！
整个程序已结束！
```

根据上述输出内容可知：

`try` 块中的语句没有发生异常，因此计算和消息输出语句全部被执行了，且 `catch` 块不生效。当 `try` 块执行完毕后， `finally` 块也被执行了。

第二步，我们使用零作为除数再次运行程序。

"TestException.java":

```java
try {
    int i = 10 / 0;
    System.out.println("i=" + i);
} catch (Exception e) {
    System.out.println("发生异常！");
} finally {
    System.out.println("善后工作完成！");
}
System.out.println("整个程序已结束！");
```

此时运行示例程序，并查看控制台输出信息：

```text
发生异常！
善后工作完成！
整个程序已结束！
```

根据上述输出内容可知：

“10除以0”这个语句出现了异常，因此后续的消息输出语句就不会被执行了，控制权转入 `catch` 块。当 `catch` 块中的语句被执行完毕后， `finally` 块也被执行了。

## 获取详细信息
在前文“示例一”中，我们使用 `catch` 语句捕获了异常，但只是简单地显示“发生异常”文本，如果我们需要获取异常的详细信息，可以使用Exception对象的 `printStackTrace()` 方法，它能够将异常的堆栈信息输出到控制台上，以便我们排查问题。

🟠 示例二：在控制台上显示异常详情。

在本示例中，我们故意制造一个异常，捕获异常后使用 `printStackTrace()` 方法将详情输出到控制台上。

"TestException.java":

```java
try {
    int i = 10 / 0;
} catch (Exception e) {
    e.printStackTrace();
}
```

此时运行示例程序，并查看控制台输出信息：

```text
java.lang.ArithmeticException: / by zero
	at net.bi4vmr.study.TestException.main(TestException.java:19)
```

根据上述输出内容可知：

`printStackTrace()` 方法输出了具体的异常信息，异常类型为ArithmeticException（算术错误）；错误消息为 `/ by zero` ；后续的内容是语句调用链，第一条为出现错误的类名与行号，然后是调用者信息，此处我们使用 `main()` 方法进行测试，已经是顶层调用者了，因此仅有一条记录。

不带参数的 `printStackTrace()` 方法在内存中使用的是非堆空间，频繁调用可能会导致内存不足，非调试场合将堆栈信息输出到控制台也没有实际意义，因此最好不要在生产环境中使用它。该方法还有两个重载方法，参数类型分别为PrintStream和PrintWriter，能够将堆栈信息写入到流中，我们可以进一步将异常信息写入文件或其他介质，这种日志记录方式性能更加友好。

## 捕获多种类型的异常
程序运行时发生的异常可能是多种多样的，我们可以编写多个 `catch` 块，每个 `catch` 块用来捕获不同的异常，分别进行相应的处理。

🟡 示例三：捕获多种类型的异常。

在本示例中，我们使用多个 `catch` 块，分别捕获不同类型的异常。

"TestException.java":

```java
try {
    int i = 10 / 0;
    System.out.println("i=" + i);
} catch (ArithmeticException ae) {
    System.out.println("除数不能为0！");
} catch (Exception e) {
    System.out.println("其它错误。");
}
```

若有多个 `catch` 块存在，程序遇到异常时将按照 `catch` 块的声明顺序依次匹配异常类型，一旦匹配成功，就会执行对应的异常处理语句，不会再匹配后续的 `catch` 块。因为Exception是所有异常的父类，我们需要将其写在最后一个 `catch` 块中，对未被明细条目匹配到的异常进行兜底处理。

此时运行示例程序，并查看控制台输出信息：

```text
除数不能为0！
```

根据上述输出内容可知：

“10除以0”这一操作触发了ArithmeticException异常，该异常被第一个 `catch` 块捕获到，系统执行了对应的异常处理语句，后续的 `catch` 块已被忽略，其中的语句没有被执行。

## 异常与"return"语句
我们可以在 `try-catch-finally` 语句中使用 `return` 语句，但需要注意每个部分的跳转规则。

🟢 示例四：异常与 `return` 语句。

在本示例中，我们故意制造一个异常，然后在 `try-catch-finally` 语句中添加 `return` 语句，测试跳转规则。

"TestException.java":

```java
String returnInTryCatch() {
    try {
        int i = 10 / 0;
        // 正常执行完毕的返回值
        return "try块中的return生效了。";
    } catch (Exception e) {
        // 出现异常情况的返回值
        return "catch块中的return生效了。";
    } finally {
        return "finally块中的return生效了。";
    }
}
```

此时运行示例程序，并查看控制台输出信息：

```text
finally块中的return生效了。
```

根据上述输出内容可知：

无论 `try` 块中的语句是否出现异常， `returnInTryCatch()` 方法都会返回 `finally` 块中所设置的字符串。

由此可见，我们不应当在 `finally` 块中使用 `return` 语句，只能在 `try` 块中返回正常情况的值； `catch` 块中返回异常情况的值。

## "try-with-resources"语法
自从Java 7开始，JDK提供了 `try-with-resources` 语法，用于简化特定场景的代码，相关语法如下文代码块所示：

```text
try (声明资源对象...) {
    <可能会发生异常的语句...>
} catch (Exception e) {
    <异常处理语句...>
}
```

我们可以在 `try` 关键字后的括号内声明实现了Closeable接口的对象，当 `try` 或 `catch` 块中的语句执行完毕后，系统将会自动调用资源对象的 `close()` 方法释放资源，我们无需声明 `finally` 块实现此逻辑。

🔵 示例五： `try-with-resources` 语法的基本应用。

在本示例中，我们从控制台读取一行文本，并将其写入文件。

第一步，我们使用普通的"try-catch-finally"语句实现该功能。

"TestException.java":

```java
Scanner scanner = new Scanner(System.in);
BufferedWriter writer = null;
try {
    System.out.println("请输入文本，按回车键确认：");
    String text = scanner.nextLine();
    writer = new BufferedWriter(new FileWriter("output.txt"));
    writer.write(text);
} catch (Exception e) {
    e.printStackTrace();
} finally {
    // 手动释放资源
    scanner.close();
    if (writer != null) {
        try {
            writer.close();
        } catch (IOException e) {
            e.printStackTrace();
        }
    }
}
```

第二步，我们使用"try-with-resources"语法实现该功能。

"TestException.java":

```java
// 在"try"后的括号内声明资源变量
try (BufferedWriter writer = new BufferedWriter(new FileWriter("output.txt"));
     Scanner scanner = new Scanner(System.in)) {
    System.out.println("请输入文本，按回车键确认：");
    String text = scanner.nextLine();
    writer.write(text);
} catch (Exception e) {
    e.printStackTrace();
}
// 上述代码执行完毕后，所有的资源都会被释放，先声明的后被释放。
```

> 🚩 提示
>
> 自从Java 9开始，我们可以在"try-with-resources"语句之前声明资源变量，并将资源变量填入"try"块后的括号中，提高代码的可读性。


# 受检异常与非受检异常
受检异常是指编码阶段不可预料的异常，例如：网络不可用、磁盘空间不足，无论我们的代码逻辑是否完善它们都可能会出现，因此编译器将会检查我们是否处理了这些异常，若未处理则报错提醒开发者完善代码。

非受检异常是指编码阶段可预料的异常，例如：空指针错误、数组越界错误，此类错误容易在测试阶段被发现并修复，我们可以完善代码逻辑进行规避，因此编译器不会强制我们处理这些异常。

在Java语言中，非受检异常都继承自RuntimeException类，例如：NullPointerException、IndexOutOfBoundsException等；其他未继承自RuntimeException类的异常均属于受检异常。


# 主动抛出异常
在前文章节中，我们以调用者视角捕获了JDK或第三方库所抛出的异常；当我们编写库以供他人使用时，可能也需要向调用者抛出异常，告知其发生了何种错误。

🟣 示例六：主动抛出异常。

在本示例中，我们编写一个方法用于计算整数角度的正切值，当输入值为90度的倍数时，向调用者抛出算术异常。

"TestException.java":

```java
public class TestException {

    public static void main(String[] args) {
        try {
            System.out.println("tan(45) = " + tan(45));
            System.out.println("tan(90) = " + tan(90));
        } catch (Exception e) {
            e.printStackTrace();
        }
    }

    private static double tan(int deg) throws ArithmeticException {
        if (deg % 90 == 0) {
			// 输入值不合法，抛出异常。
            throw new ArithmeticException();
        } else {
			// 输入值合法，返回计算结果。
            return Math.tan(Math.toRadians(deg));
        }
    }
}
```

在上述代码中，我们对 `double tan(int deg)` 方法的输入参数进行校验，如果参数不合法，则使用 `throw` 关键字抛出异常。 `throw` 关键字后是一个异常对象，部分异常对象可以设置错误码等详细信息；此处我们使用系统内置的ArithmeticException，它不支持任何附加信息，我们只是简单地创建对象。

一个方法中若存在抛出受检异常的语句，或调用了其他可能抛出受检异常的方法且未经捕获处理，则必须在方法声明语句的参数列表后使用 `throws` 关键字列出这些异常，提醒方法的调用者需要进一步处理，如有多种异常时以逗号( `,` )分隔。

此时运行示例程序，并查看控制台输出信息：

```text
tan(45) = 0.9999999999999999
java.lang.ArithmeticException
    at net.bi4vmr.study.TestException.tan(TestException.java:160)
    at net.bi4vmr.study.TestException.main(TestException.java:21)
```


# 自定义异常
当我们编写业务代码时，如果系统内置异常的语义能够满足要求，可以直接使用它们；如果内置异常无法满足要求，我们则需要自定义新的异常。

异常以类的形式存在，自定义异常需要继承系统中已有的异常类，我们通常继承Exception类，并按需添加其他属性与方法。

🟤 示例七：定义并使用自定义异常。

在本示例中，我们创建一个自定义异常类，在测试方法中抛出并捕获该异常。

第一步，我们创建CustomException类，它就是自定义异常类，拥有错误码属性。

"CustomException.java":

```java
public class CustomException extends Exception {

    // 错误码
    private final int code;

    // 构造方法，用于创建异常对象。
    public CustomException(int code, String message) {
        super(message);
        this.code = code;
    }

    // 获取错误码
    public int getCode() {
        return code;
    }
}
```

第二步，我们在 `raiseException()` 方法中抛出CustomException，并设置错误码为 `100` ，消息为“自定义异常”，然后以 `main()` 方法模拟调用者，捕获异常并向控制台输出异常信息。

"TestException.java":

```java
public class TestException {

    public static void main(String[] args) {
        try {
            raiseException();
        } catch (CustomException e) {
            System.out.println("遇到异常：" + e.getMessage());
            System.out.println("错误码：" + e.getCode());
        }
    }

    private static void raiseException() throws CustomException {
        throw new CustomException(100, "自定义异常");
    }
}
```

此时运行示例程序，并查看控制台输出信息：

```text
遇到异常：自定义异常
错误码：100
```


# 异常链
我们在编写库或者中间件时，可能需要将底层发生的异常转换为另一种异常，向调用者描述更加详细的原因，同时保留原始异常信息以便调用者进行分析。例如：在加载图片时，系统汇报文件未找到异常，我们可以将该异常包装在自定义异常中，添加状态码和图片路径，以便上层进一步处理。

将原始异常封装在另一个异常中再抛出的功能，被称为“异常链”，这是一种面向对象的编程方法。

🔴 示例八：异常链的基本应用。

在本示例中，我们故意制造一个算术异常，并将其捕获后转为前文“示例七”中的CustomException，再向调用者抛出。

"TestException.java":

```java
public class TestException {

    public static void main(String[] args) {
        try {
            convertException();
        } catch (CustomException e) {
            e.printStackTrace();
        }
    }

    private static void convertException() throws CustomException {
        try {
            int i = 10 / 0;
        } catch (ArithmeticException ae) {
            System.out.println("捕获算术异常，将其转换为自定义异常再向上层抛出。");
            CustomException customException = new CustomException(99, "自定义异常");
            // 使用 `initCause()` 方法指明引起CustomException的原始异常
            customException.initCause(ae);
            // 抛出新建的CustomException
            throw customException;
        }
    }
}
```

此处的 `convertException()` 方法实现了异常转换，它会抛出CustomException异常，我们以 `main()` 方法模拟调用者，捕获异常并向控制台输出异常信息。

在 `convertException()` 方法中，我们使用CustomException对象的 `initCause()` 方法设置原始异常信息，随后将其抛出给调用者。

此时运行示例程序，并查看控制台输出信息：

```text
捕获算术异常，将其转换为自定义异常再向上层抛出。
net.bi4vmr.study.exception.CustomException: 自定义异常
    at net.bi4vmr.study.TestException.convertException(TestException.java:201)
    at net.bi4vmr.study.TestException.main(TestException.java:20)
Caused by: java.lang.ArithmeticException: / by zero
    at net.bi4vmr.study.TestException.convertException(TestException.java:198)
    ... 1 more
```

根据上述输出内容可知：

堆栈信息中的 `Caused by:` 部分即表示引起该异常的原始异常信息。
