# 简介
当程序运行时，外部环境不一定总能满足条件，例如：我们准备向磁盘中写入一些数据，但磁盘的剩余空间可能不足，即使我们在写入前检查剩余空间，写入过程中磁盘仍然可以被其他程序填满，从而导致写入失败。

阻止当前程序正确执行的问题，被称为“异常(Exception)”，我们可以捕获异常并根据情况进行适当的处理，以确保程序能够继续运行。

Java中的异常都继承自Throwable类，随后可以分为两个大类：Error和Exception。Error表示系统错误，通常由JVM汇报，原因包括虚拟机错误、内存溢出、线程死锁等，此类错误一般无法处理，因为它们发生之后程序将会崩溃。Exception则表示用户态错误，原因包括编码问题、环境问题、用户操作失误等，此类错误仅影响程序正在执行的语句，妥善处理后程序可以继续运行。

常见的Exception如下文列表所示：

- RuntimeException（运行时异常）
- NullPointerException（空指针异常）
- ClassCastException（类型转换异常）
- ArrayIndexOutOfBoundsException（数组下标越界异常）
- ArithmeticException（算术异常）
- CheckException（检查异常）
- IOException（文件异常）
- SQLException（SQL异常）

# 捕获并处理异常
## 简介
默认情况下，当某个语句出现异常后，其所在的线程就会立刻终止，相关资源无法被释放，外部组件也不会感知到该事件。

我们可以使用"try ... catch ... finally"语句捕获并处理异常，释放当前线程所关联的资源或者向用户展示错误提示信息，相关语法如下文代码块所示：

```text
try {
    <可能会发生异常的语句...>
} catch (Exception e) {
    <异常处理语句...>
} finally {
    <公共语句...>
}
```

"try"块中的语句将会按顺序执行，一旦遇到错误，就会忽略后续语句，并将控制权交给"catch"块，执行其中的异常处理语句。"finally"块中的语句用于执行一些善后操作，不管是否发生异常都会执行，一般用于关闭I/O流等，如果我们不需要此类操作，也可以省略"finally"块。

## 基本应用
以下示例展示了异常的捕获与处理方法：

🔴 示例一

我们首先书写一段不会发生异常的程序：

"TestException.java":

```java
try {
    int i = 10 / 5;
    System.out.println("i=" + i);
} catch (Exception e) {
    System.out.println("发生异常！");
} finally {
    System.out.println("善后工作完成！");
}
System.out.println("整个程序已结束！");
```

此时运行示例程序，并查看控制台输出信息：

```text
i=2
善后工作完成！
整个程序已结束！
```

在上述代码中，"try"块中的语句没有发生异常，因此这些语句全部被执行了，且"catch"块不生效。当"try"块执行完毕后，"finally"块也被执行了。

接下来，我们再书写一段会发生异常的程序：

"TestException.java":

```java
try {
    int i = 10 / 0;
    System.out.println("i=" + i);
} catch (Exception e) {
    System.out.println("发生异常！");
} finally {
    System.out.println("善后工作完成！");
}
System.out.println("整个程序已结束！");
```

此时运行示例程序，并查看控制台输出信息：

```text
发生异常！
善后工作完成！
整个程序已结束！
```

在上述代码中，“10除以0”这个语句出现了异常，后续的消息输出语句就不会被执行了，控制权转入"catch"块；当"catch"块中的语句被执行完毕后，再执行"finally"块中的语句。

## 获取详细信息
在前文“示例一”中，我们使用"catch"语句捕获了异常，但只是简单的显示“发生异常”文本，如果我们需要获取异常的详细信息，可以使用Exception实例的 `printStackTrace()` 方法，它能够将异常的堆栈信息输出到控制台上，以便我们排查问题。

🟠 示例二

我们主动制造一个异常，捕获异常后使用 `printStackTrace()` 方法将详情输出到控制台上。

"TestException.java":

```java
try {
    int i = 10 / 0;
} catch (Exception e) {
    e.printStackTrace();
}
```

此时运行示例程序，并查看控制台输出信息：

```text
java.lang.ArithmeticException: / by zero
	at net.bi4vmr.study.exception.TestException.example02(ExceptionDemo.java:34)
	at net.bi4vmr.study.exception.TestException.main(ExceptionDemo.java:17)
```

`printStackTrace()` 方法输出了具体的异常信息，异常类型为ArithmeticException（算术错误）；错误消息为"/ by zero"；后续的内容是语句调用链，第一条为出现错误的类名与行号，然后是调用者信息，此处我们使用"main"方法进行测试，已经是顶层调用者了，因此仅有一条记录。

不带参数的 `printStackTrace()` 方法在内存中使用的是非堆空间，频繁调用可能会导致内存不足，非调试场合将堆栈信息输出到控制台也没有实际意义，因此最好不要在生产环境中使用它。该方法还有两个重载方法，参数类型分别为PrintStream和PrintWriter，可以将堆栈信息写入到流中，这种方式能够进行性能友好的日志记录。

## 捕获多种类型的异常
程序运行时发生的异常可能是多种多样的，我们可以设置多个"catch"块，每个"catch"块用来捕捉不同的异常，分别进行不同的处理。

🟡 示例三

若有多个"catch"块存在，程序遇到异常时将按照"catch"块的书写顺序依次匹配异常类型，一旦匹配成功，就会执行对应的异常处理语句，不会再匹配后续"cache"块。因为Exception是所有异常的父类，我们需要将其写在最后一个"cache"块中，对未特殊处理的异常进行兜底。

"TestException.java":

```java
try {
    int i = 10 / 0;
    System.out.println("i=" + i);
} catch (ArithmeticException ae) {
    System.out.println("除数不能为0！");
} catch (Exception e) {
    System.out.println("其它错误。");
}
```

此时运行示例程序，并查看控制台输出信息：

```text
除数不能为0！
```

在上述代码中，“10除以0”这一操作触发了ArithmeticException异常，该异常被第一个"cache"块捕获到，系统执行了对应的异常处理语句，后续的"cache"块已被忽略，其中的语句没有被执行。

## 异常与"return"语句
我们可以在"try ... catch ... finally"语句中使用"return"语句，但需要注意每个语句的跳转规则。

🟢 示例四

我们主动制造一个异常，然后在"try ... catch ... finally"语句中调用"return"语句，测试它们的跳转规则。

"TestException.java":

```java
static String returnInTryCatch() {
    try {
        int i = 10 / 0;
        // 正常执行完毕的返回值
        return "try块中的return生效了。";
    } catch (Exception e) {
        // 出现异常情况的返回值
        return "catch块中的return生效了。";
    } finally {
        return "finally块中的return生效了。";
    }
}
```

此时运行示例程序，并查看控制台输出信息：

```text
finally块中的return生效了。
```

在上述示例中，无论"try"块中的语句是否出现异常， `returnInTryCatch()` 方法都会返回"finally"块中所设置的字符串。

由此可见，我们不应当在"finally"块中使用"return"语句，只能在"try"块中返回正常情况的值；"catch"块中返回异常情况的值。

# 主动抛出异常
前文介绍了如何处理系统或第三方库抛出的异常，当我们编写库或方法供他人使用时，可能需要向调用者抛出异常，告知其发生了何种错误，以便其进行相应的处理。

此处我们编写一个方法用于计算整数角度的正切值，当输入值为90度的倍数时，向外抛出算术异常。

"TestException.java":

```java
public class TestException {

    public static void main(String[] args) {
        try {
            System.out.println("tan(45) = " + tan(45));
            System.out.println("tan(90) = " + tan(90));
        } catch (Exception e) {
            e.printStackTrace();
        }
    }

    private static double tan(int deg) throws ArithmeticException {
        if (deg % 90 == 0) {
			// 输入值不合法，抛出异常。
            throw new ArithmeticException();
        } else {
			// 输入值合法，返回计算结果。
            return Math.tan(Math.toRadians(deg));
        }
    }
}
```

在上述示例代码中，我们对 `double tan(int deg)` 方法的输入参数进行校验，如果参数不合法，则使用"throw"关键字抛出异常。"throw"关键字后是一个异常对象，部分异常对象可以设置错误码与消息；此处我们使用系统内置的算术异常，它不支持任何自定义属性，我们只是简单的创建对象。

我们自定义的方法若有抛出异常的可能，需要在参数列表后使用"throws"关键字将异常列出，有多个类型的异常时以逗号(",")分隔。调用这类方法的上层代码，必须使用 `try ... catch` 进行捕获，否则无法通过编译。

此时运行示例程序，并查看控制台输出信息：

```text
tan(45) = 0.9999999999999999
Exception in thread "main" java.lang.ArithmeticException
	at net.bi4vmr.study.exception.TestException.tan(ExceptionDemo.java:76)
	at net.bi4vmr.study.exception.TestException.main(ExceptionDemo.java:19)
```

# 自定义异常
对于我们自己编写的业务逻辑，可以使用自定义异常描述各种意外情况。自定义异常类需要继承系统中已存在的异常类，我们通常直接继承Exception类。

此处我们创建一个异常类CustomException，它拥有错误码属性。

"CustomException.java":

```java
// 自定义异常类
public class CustomException extends Exception {

    // 错误码
    private final int code;

    // 构造方法，用于创建异常对象。
    public CustomException(int code, String message) {
        super(message);
        this.code = code;
    }

    // 获取错误码
    public int getCode() {
        return code;
    }
}
```

我们在 `raiseException()` 方法中抛出自定义异常，并设置错误码为100，消息为“自定义异常”，然后尝试捕获自定义异常。

"TestException.java":

```java
public class TestException {

    public static void main(String[] args) {
        try {
            raiseException();
        } catch (CustomException e) {
            System.out.println("遇到异常：" + e.getMessage());
            System.out.println("错误码：" + e.getCode());
        }
    }

    private static void raiseException() throws CustomException {
        throw new CustomException(100, "自定义异常");
    }
}
```

此时运行示例程序，并查看控制台输出信息：

```text
遇到异常：自定义异常
错误码：100
```

# 异常链
我们在编写库或者中间件时，可能需要将底层发生的异常转换为另一种的异常，向上层描述更加详细的原因，同时保留原始异常信息。例如：加载图片时，系统汇报文件未找到异常，我们可以将该异常包装在自定义异常中，添加状态码和图片路径，以便上层进一步处理。

将原始异常封装在另一个异常中抛出的功能，被称为“异常链”，这是一种面向对象的编程方法。我们以前文的CustomException为例，将捕获到的算术异常转为CustomException，并向调用者抛出。

"TestException.java":

```java
public class TestException {

    public static void main(String[] args) {
        try {
            convertException();
        } catch (CustomException e) {
            e.printStackTrace();
        }
    }

    private static void convertException() throws CustomException {
        try {
            int i = 10 / 0;
        } catch (ArithmeticException ae) {
            System.out.println("捕获算术异常，将其转换为自定义异常再向上层抛出。");
            CustomException customException = new CustomException(99, ae.getMessage());
            // 使用"initCause()"方法指明引起CustomException的原始异常
            customException.initCause(ae);
            // 抛出新建的CustomException
            throw customException;
        }
    }
}
```

我们使用CustomException对象的 `initCause()` 方法，设置了原始异常信息，随后将其抛出给调用者。

此时运行示例程序，并查看控制台输出信息：

```text
捕获算术异常，将其转换为自定义异常再向上层抛出。
net.bi4vmr.study.exception.TestException: / by zero
	at net.bi4vmr.study.exception.TestException.convertException(ExceptionDemo.java:108)
	at net.bi4vmr.study.exception.TestException.main(ExceptionDemo.java:19)
Caused by: java.lang.ArithmeticException: / by zero
	at net.bi4vmr.study.exception.TestException.convertException(ExceptionDemo.java:105)
	... 1 more
```

上述堆栈信息中，"Caused by:"部分即表示引起该异常的原始异常信息。
