# 简介
当程序运行时，外部环境不一定总能满足条件，例如：我们准备向磁盘中写入一些数据，但磁盘的剩余空间可能不足，即使我们在写入前已检查剩余空间，写入过程中磁盘仍然可能被其他程序填满，从而导致写入失败。

阻止程序正确运行的问题被统称为“异常(Exception)”，我们可以在编码阶段对常见的异常进行处理，最大程度上确保程序运行稳定。

Kotlin中的异常继承自Throwable类，随后可以分为两个大类：Error和Exception。Error表示系统级错误，通常由JVM汇报，包括：虚拟机错误、内存溢出、线程死锁等，开发者在编码阶段无需处理此类错误，因为它们出现之后当前程序甚至整个系统可能崩溃，需要重启程序或系统、扩充物理内存或调整代码逻辑才能解决问题。Exception则表示用户态错误，包括：网络不可用、磁盘已满、用户输入参数错误等，此类错误仅影响程序正在执行的语句，开发者可以提醒用户解决问题后重试。

Kotlin中常见的异常如下文表格所示：

<div align="center">

|            异常类名            |       含义       |                           示例                           |
| :----------------------------: | :--------------: | :------------------------------------------------------: |
|      NullPointerException      |    空指针异常    |        `val text: String? = null; text!!.length;`        |
|       ClassCastException       |   类型转换异常   |                 `Any a = "A"; (Int) a;`                  |
| ArrayIndexOutOfBoundsException | 数组下标越界异常 | `val array = intArrayOf(0, 1, 2); val item = array[10];` |
|      ArithmeticException       |     算术异常     |          `val a = 10; val b = 0; val z = a / b`          |
|          IOException           |     I/O异常      |                  写入数据时目标磁盘已满                  |
|          SQLException          |     SQL异常      |                       SQL语法错误                        |

</div>


# 捕获异常
## 简介
默认情况下，当程序运行中某个语句出现异常时，其所属线程就会立刻终止，相关资源无法得到释放，外部组件也不会感知到该事件。

我们可以使用 `try-catch-finally` 语句捕获可能出现的异常，并释放当前线程所关联的资源或者向用户展示错误提示信息，相关语法如下文代码块所示：

```text
try {
    <可能会发生异常的语句...>
} catch (e: Exception) {
    <异常处理语句...>
} finally {
    <公共语句...>
}
```

`try` 块中的语句将会按照顺序执行，一旦某个语句出现异常，程序就会忽略后续语句，并将控制权移交给 `catch` 块，按照顺序执行其中的异常处理语句。 `finally` 块中的语句用于执行善后操作，不管是否发生异常都会在最后被执行，我们可以在此处放置关闭I/O流、删除临时文件等语句，若我们不需要任何善后操作，也可以省略 `finally` 块。

## 基本应用
下文示例展示了异常捕获语句的基本使用方法：

🔴 示例一：异常捕获语句的基本应用。

在本示例中，我们将两个整数相除的语句放置在 `try-catch-finally` 语句中，使用不同的值多次运行程序，对比程序的行为。

第一步，我们使用非零的除数运行程序。

"TestException.kt":

```kotlin
try {
    val i = 10 / 5
    println("i=$i")
} catch (e: java.lang.Exception) {
    println("发生异常！")
} finally {
    println("善后工作完成！")
}
println("整个程序已结束！")
```

此时运行示例程序，并查看控制台输出信息：

```text
i=2
善后工作完成！
整个程序已结束！
```

根据上述输出内容可知：

`try` 块中的语句没有发生异常，因此计算和消息输出语句全部被执行了，且 `catch` 块不生效。当 `try` 块执行完毕后， `finally` 块也被执行了。

第二步，我们使用零作为除数再次运行程序。

"TestException.kt":

```kotlin
try {
    val i = 10 / 0
    println("i=$i")
} catch (e: java.lang.Exception) {
    println("发生异常！")
} finally {
    println("善后工作完成！")
}
println("整个程序已结束！")
```

此时运行示例程序，并查看控制台输出信息：

```text
发生异常！
善后工作完成！
整个程序已结束！
```

根据上述输出内容可知：

“10除以0”这个语句出现了异常，因此后续的消息输出语句就不会被执行了，控制权转入 `catch` 块。当 `catch` 块中的语句被执行完毕后， `finally` 块也被执行了。

## 获取详细信息
在前文“示例一”中，我们使用 `catch` 语句捕获了异常，但只是简单地显示“发生异常”文本，如果我们需要获取异常的详细信息，可以使用Exception对象的 `printStackTrace()` 方法，它能够将异常的堆栈信息输出到控制台上，以便我们排查问题。

🟠 示例二：在控制台上显示异常详情。

在本示例中，我们故意制造一个异常，捕获异常后使用 `printStackTrace()` 方法将详情输出到控制台上。

"TestException.kt":

```kotlin
try {
    val i = 10 / 0
} catch (e: Exception) {
    e.printStackTrace()
}
```

此时运行示例程序，并查看控制台输出信息：

```text
java.lang.ArithmeticException: / by zero
	at net.bi4vmr.study.TestExceptionKt.main(TestException.kt:15)
	at net.bi4vmr.study.TestExceptionKt.main(TestException.kt)
```

根据上述输出内容可知：

`printStackTrace()` 方法输出了具体的异常信息，异常类型为ArithmeticException（算术错误）；错误消息为 `/ by zero` ；后续的内容是语句调用链，第一条为出现错误的类名与行号，然后是调用者信息，此处我们使用 `main()` 方法进行测试，已经是顶层调用者了，因此仅有一条记录。

不带参数的 `printStackTrace()` 方法在内存中使用的是非堆空间，频繁调用可能会导致内存不足，非调试场合将堆栈信息输出到控制台也没有实际意义，因此最好不要在生产环境中使用它。该方法还有两个重载方法，参数类型分别为PrintStream和PrintWriter，能够将堆栈信息写入到流中，我们可以进一步将异常信息写入文件或其他介质，这种日志记录方式性能更加友好。

## 捕获多种类型的异常
程序运行时发生的异常可能是多种多样的，我们可以编写多个 `catch` 块，每个 `catch` 块用来捕获不同的异常，分别进行相应的处理。

🟡 示例三：捕获多种类型的异常。

在本示例中，我们使用多个 `catch` 块，分别捕获不同类型的异常。

"TestException.kt":

```kotlin
try {
    val i = 10 / 0
} catch (ae: ArithmeticException) {
    println("除数不能为0！")
} catch (e: Exception) {
    println("其它错误。")
}
```

若有多个 `catch` 块存在，程序遇到异常时将按照 `catch` 块的声明顺序依次匹配异常类型，一旦匹配成功，就会执行对应的异常处理语句，不会再匹配后续的 `catch` 块。因为Exception是所有异常的父类，我们需要将其写在最后一个 `catch` 块中，对未被明细条目匹配到的异常进行兜底处理。

此时运行示例程序，并查看控制台输出信息：

```text
除数不能为0！
```

根据上述输出内容可知：

“10除以0”这一操作触发了ArithmeticException异常，该异常被第一个 `catch` 块捕获到，系统执行了对应的异常处理语句，后续的 `catch` 块已被忽略，其中的语句没有被执行。

## 异常与"return"语句
我们可以在 `try-catch-finally` 语句中使用 `return` 语句，但需要注意每个部分的跳转规则。

🟢 示例四：异常与 `return` 语句。

在本示例中，我们故意制造一个异常，然后在 `try-catch-finally` 语句中添加 `return` 语句，测试跳转规则。

"TestException.kt":

```kotlin
fun returnInTryCatch(): String {
    try {
        10 / 0
        return "try块中的return生效了。"
    } catch (e: Exception) {
        // 出现异常情况的返回值
        return "catch块中的return生效了。"
    } finally {
        return "finally块中的return生效了。"
    }
}
```

此时运行示例程序，并查看控制台输出信息：

```text
finally块中的return生效了。
```

根据上述输出内容可知：

无论 `try` 块中的语句是否出现异常， `returnInTryCatch()` 方法都会返回 `finally` 块中所设置的字符串。

由此可见，我们不应当在 `finally` 块中使用 `return` 语句，只能在 `try` 块中返回正常情况的值； `catch` 块中返回异常情况的值。

## "runCatching"函数
`runCatching()` 是一个内置函数，它与 `try-catch` 语句的作用类似，但更符合函数式编程风格。

🔵 示例五： `runCatching()` 函数的基本应用。

在本示例中，我们使用 `runCatching()` 函数代替 `try-catch` 语法。

"TestException.kt":

```kotlin
runCatching {
    val i = 10 / 5
    println("i=$i")
    // 返回一个数值
    i
}.onSuccess { result ->
    println("操作完毕，未发生异常！")
    println("接收到返回值：$result")
}.onFailure { e ->
    println("发生异常！${e.message}")
}
```

`runCatching(block: () -> R)` 函数将会执行参数 `block` 所指代的语句，如果发生异常则触发 `onFailure()` 函数，参数为异常信息；如果所有语句都未出现错误，则触发 `onSuccess()` 函数，参数为 `runCatching()` 的返回值。

此时运行示例程序，并查看控制台输出信息：

```text
操作完毕，未发生异常！
接收到返回值：2
```

## "use"函数
`use()` 是一个扩展函数，我们可以在实现了Closeable接口的对象上使用它，`use(block: (T) -> R)` 将会执行参数 `block` 所指代的语句，语句全部执行完毕或出现异常后， `use()` 函数将会调用目标对象的 `close()` 方法释放资源。

🟣 示例六： `use()` 函数的基本应用。

在本示例中，我们从控制台读取一行文本，并将其写入文件。

"TestException.kt":

```kotlin
val scanner = Scanner(System.`in`)
scanner.use {
    BufferedWriter(FileWriter("output.txt")).use {
        println("请输入文本，按回车键确认：")
        val text = scanner.nextLine()
        it.write(text)
    }
}
```

如果释放资源时出现异常， `use()` 函数会忽略这些异常；如果执行 `block` 中的语句时出现异常， `use()` 函数会抛出它们，我们可以结合 `try-catch` 语句进行处理。


# 受检异常与非受检异常
受检异常是指编码阶段不可预料的异常，例如：网络不可用、磁盘空间不足，无论我们的代码逻辑是否完善它们都可能会出现，因此编译器将会检查我们是否处理了这些异常，若未处理则报错提醒开发者完善代码。

非受检异常是指编码阶段可预料的异常，例如：空指针错误、数组越界错误，此类错误容易在测试阶段被发现并修复，我们可以完善代码逻辑进行规避，因此编译器不会强制我们处理这些异常。

在Kotlin语言中，所有的异常均属于非受检异常，编译器不会强制调用者编写捕获与处理逻辑。


# 主动抛出异常
在前文章节中，我们以调用者视角捕获了JDK或第三方库所抛出的异常；当我们编写库以供他人使用时，可能也需要向调用者抛出异常，告知其发生了何种错误。

🟤 示例七：主动抛出异常。

在本示例中，我们编写一个方法用于计算整数角度的正切值，当输入值为90度的倍数时，向调用者抛出算术异常。

"TestException.kt":

```kotlin
try {
    println("tan(45) = ${tan(45)}")
    println("tan(90) = ${tan(90)}")
} catch (e: Exception) {
    e.printStackTrace()
}

fun tan(deg: Int): Double {
    if (deg % 90 == 0) {
        throw ArithmeticException()
    } else {
        return kotlin.math.tan(Math.toRadians(deg.toDouble()))
    }
}
```

在上述代码中，我们对 `tan(deg: Int): Double` 方法的输入参数进行校验，如果参数不合法，则使用 `throw` 关键字抛出异常。 `throw` 关键字后是一个异常对象，部分异常对象可以设置错误码等详细信息；此处我们使用系统内置的ArithmeticException，它不支持任何附加信息，我们只是简单地创建对象。

此时运行示例程序，并查看控制台输出信息：

```text
tan(45) = 0.9999999999999999
java.lang.ArithmeticException
	at net.bi4vmr.study.TestExceptionKt.tan(TestException.kt:53)
	at net.bi4vmr.study.TestExceptionKt.main(TestException.kt:14)
	at net.bi4vmr.study.TestExceptionKt.main(TestException.kt)
```


# 自定义异常
当我们编写业务代码时，如果系统内置异常的语义能够满足要求，可以直接使用它们；如果内置异常无法满足要求，我们则需要自定义新的异常。

异常以类的形式存在，自定义异常需要继承系统中已有的异常类，我们通常继承Exception类，并按需添加其他属性与方法。

🔴 示例八：定义并使用自定义异常。

在本示例中，我们创建一个自定义异常类，在测试方法中抛出并捕获该异常。

第一步，我们创建CustomException类，它就是自定义异常类，拥有错误码属性。

"CustomException.kt":

```kotlin
class CustomException(

    // 错误码
    private val code: Int,

    // 错误信息
    info: String
) : Exception(info) {

    // 获取错误码
    fun getCode(): Int {
        return code
    }
}
```

第二步，我们在 `raiseException()` 方法中抛出CustomException，并设置错误码为 `100` ，消息为“自定义异常”，然后以 `main()` 方法模拟调用者，捕获异常并向控制台输出异常信息。

"TestException.kt":

```kotlin
fun main() {
    try {
        raiseException()
    } catch (e: CustomException) {
        println("遇到异常：${e.message}")
        println("错误码：${e.getCode()}")
    }
}

fun raiseException() {
    throw CustomException(100, "自定义异常")
}
```

此时运行示例程序，并查看控制台输出信息：

```text
遇到异常：自定义异常
错误码：100
```


# 异常链
我们在编写库或者中间件时，可能需要将底层发生的异常转换为另一种异常，向调用者描述更加详细的原因，同时保留原始异常信息以便调用者进行分析。例如：在加载图片时，系统汇报文件未找到异常，我们可以将该异常包装在自定义异常中，添加状态码和图片路径，以便上层进一步处理。

将原始异常封装在另一个异常中再抛出的功能，被称为“异常链”，这是一种面向对象的编程方法。

🟠 示例九：异常链的基本应用。

在本示例中，我们故意制造一个算术异常，并将其捕获后转为前文“示例七”中的CustomException，再向调用者抛出。

"TestException.kt":

```kotlin
fun main() {
    try {
        convertException()
    } catch (e: Exception) {
        e.printStackTrace()
    }
}

fun convertException() {
    try {
        10 / 0
    } catch (ae: ArithmeticException) {
        println("捕获算术异常，将其转换为自定义异常再向上层抛出。")
        val customException = CustomException(100, "自定义异常")
        // 使用 `initCause()` 方法指明引起CustomException的原始异常
        customException.initCause(ae)
        // 抛出新建的CustomException
        throw customException
    }
}
```

此处的 `convertException()` 方法实现了异常转换，它会抛出CustomException异常，我们以 `main()` 方法模拟调用者，捕获异常并向控制台输出异常信息。

在 `convertException()` 方法中，我们使用CustomException对象的 `initCause()` 方法设置原始异常信息，随后将其抛出给调用者。

此时运行示例程序，并查看控制台输出信息：

```text
捕获算术异常，将其转换为自定义异常再向上层抛出。
net.bi4vmr.study.exception.CustomException: 自定义异常
	at net.bi4vmr.study.TestExceptionKt.convertException(TestException.kt:71)
	at net.bi4vmr.study.TestExceptionKt.main(TestException.kt:13)
	at net.bi4vmr.study.TestExceptionKt.main(TestException.kt)
Caused by: java.lang.ArithmeticException: / by zero
	at net.bi4vmr.study.TestExceptionKt.convertException(TestException.kt:68)
	... 2 more
```

根据上述输出内容可知：

堆栈信息中的 `Caused by:` 部分即表示引起该异常的原始异常信息。


# 与Java交互
## 声明方法可能抛出的异常
Kotlin语言不支持受检异常，因此Kotlin中的方法也无法使用Java的 `throws` 关键字声明可能出现的异常，我们在Java中调用Kotlin方法时也不会触发受检异常强制检查。

为了解决上述问题，Kotlin提供了 `@Throws` 注解，我们可以将其添加到方法上，并传入方法可能出现的异常，此时Java侧将会触发受检异常强制检查。

🟡 示例十：声明方法可能抛出的异常。

在本示例中，我们自定义一个方法，并使用 `@Throws` 注解声明可能出现的异常。

"TestException.kt":

```kotlin
@Throws(IOException::class, SocketException::class)
fun javaExceptionTest() { }
```
